Workbook

Sheet Instructions
A1: Unisex Salon — Price List, Profit & Margin Calculator
A3: HOW TO USE THIS WORKBOOK
A5: 1. Go to the 'Price List & Margins' tab. Every service from the salon's rate card is listed there, grouped by category, with its Selling Price already filled in from the uploaded menu.
A6: 2. Fill in your own COST for each service in the yellow 'Cost per Service' column (column E). This should be your fully-loaded cost: consumables/products used, staff time (wage per minute x service duration), electricity, and any other direct cost. Row 6 (Threading - Upper Lips) shows an example — replace it with your real numbers.
A7: 3. Profit (Rs.) and Margin % calculate automatically as soon as you enter a cost — you don't need to touch columns F or G.
A8: 4. The 'Category Summary' tab automatically rolls up average price, average cost, average profit and average margin for every category, plus an overall salon-wide summary, once you've filled in costs.
A10: COLOR KEY
A11: Yellow cells = type your own numbers here (Cost per Service).
A12: Blue text = hardcoded input.
A13: Black text = formula — do not overwrite.
A15: NOTES ON THE SOURCE MENU
A16: Several numbers in the photographed rate card were partly obscured by glare, correction fluid, or handwriting over the printed price. Those cells are flagged in the 'Notes' column (H) — please verify the actual price with the salon's current physical menu/POS before relying on the Profit/Margin figures for those specific rows. All other prices are transcribed directly as printed on the uploaded menu.
... A24: Treatment plan for hair - 800Rs - 5kg - 5000 profit 10 Boxes(1 box cost - 600) and Shampoo 500Rs 1ltr cost per box 1600

Sheet Price List & Margins
A1: Category | B1: Service | C1: Variant | D1: Selling Price (Rs.) | E1: Cost per Service (Rs.) | F1: Profit (Rs.) | G1: Margin % | H1: Notes
A2: Threading | B2: Upper Lips | D2: 30 | E2: 5 | F2: =IF(E2="","",D2-E2) -> 25 | G2: =IFERROR(IF(E2="","",F2/D2),"") -> 0.83333333
A3: Threading | B3: Eye Brow | D3: 50 | E3: 5 | F3: =IF(E3="","",D3-E3) -> 45 | G3: =IFERROR(IF(E3="","",F3/D3),"") -> 0.9
A4: Threading | B4: Forehead | D4: 30 | E4: 5 | F4: =IF(E4="","",D4-E4) -> 25 | G4: =IFERROR(IF(E4="","",F4/D4),"") -> 0.83333333
A5: Threading | B5: Cheeks | D5: 50 | E5: 5 | F5: =IF(E5="","",D5-E5) -> 45 | G5: =IFERROR(IF(E5="","",F5/D5),"") -> 0.9
A6: Threading | B6: Chin | D6: 30 | E6: 5 | F6: =IF(E6="","",D6-E6) -> 25 | G6: =IFERROR(IF(E6="","",F6/D6),"") -> 0.83333333
A7: Threading | B7: Full Face | D7: 250 | E7: 15 | F7: =IF(E7="","",D7-E7) -> 235 | G7: =IFERROR(IF(E7="","",F7/D7),"") -> 0.94
A8: Brazilian Face Wax | B8: Upper Lips | D8: 50 | E8: 5 | F8: =IF(E8="","",D8-E8) -> 45 | G8: =IFERROR(IF(E8="","",F8/D8),"") -> 0.9
A9: Brazilian Face Wax | B9: Eye Brow | D9: 100 | E9: 5 | F9: =IF(E9="","",D9-E9) -> 95 | G9: =IFERROR(IF(E9="","",F9/D9),"") -> 0.95
A10: Brazilian Face Wax | B10: Forehead | D10: 50 | E10: 5 | F10: =IF(E10="","",D10-E10) -> 45 | G10: =IFERROR(IF(E10="","",F10/D10),"") -> 0.9
A11: Brazilian Face Wax | B11: Cheeks | D11: 50 | E11: 5 | F11: =IF(E11="","",D11-E11) -> 45 | G11: =IFERROR(IF(E11="","",F11/D11),"") -> 0.9
A12: Brazilian Face Wax | B12: Chin | D12: 50 | E12: 5 | F12: =IF(E12="","",D12-E12) -> 45 | G12: =IFERROR(IF(E12="","",F12/D12),"") -> 0.9
A13: Brazilian Face Wax | B13: Full Face | D13: 400 | E13: 50 | F13: =IF(E13="","",D13-E13) -> 350 | G13: =IFERROR(IF(E13="","",F13/D13),"") -> 0.875
A14: Protein Bleach | B14: Face | C14: Fruit | D14: 250 | E14: 10 | F14: =IF(E14="","",D14-E14) -> 240 | G14: =IFERROR(IF(E14="","",F14/D14),"") -> 0.96
A15: Protein Bleach | B15: Face | C15: Gold | D15: 250 | E15: 10 | F15: =IF(E15="","",D15-E15) -> 240 | G15: =IFERROR(IF(E15="","",F15/D15),"") -> 0.96
A16: Protein Bleach | B16: Face | C16: Oxy | D16: 300 | E16: 10 | F16: =IF(E16="","",D16-E16) -> 290 | G16: =IFERROR(IF(E16="","",F16/D16),"") -> 0.96666667 | H16: Price partly obscured in source photo - please verify
A17: Protein Bleach | B17: Half Front | C17: Fruit | D17: 200 | E17: 10 | F17: =IF(E17="","",D17-E17) -> 190 | G17: =IFERROR(IF(E17="","",F17/D17),"") -> 0.95
A18: Protein Bleach | B18: Half Front | C18: Gold | D18: 250 | E18: 10 | F18: =IF(E18="","",D18-E18) -> 240 | G18: =IFERROR(IF(E18="","",F18/D18),"") -> 0.96
A19: Protein Bleach | B19: Half Front | C19: Oxy | D19: 300 | E19: 10 | F19: =IF(E19="","",D19-E19) -> 290 | G19: =IFERROR(IF(E19="","",F19/D19),"") -> 0.96666667
A20: Protein Bleach | B20: Half Back | C20: Fruit | D20: 200 | E20: 10 | F20: =IF(E20="","",D20-E20) -> 190 | G20: =IFERROR(IF(E20="","",F20/D20),"") -> 0.95
A21: Protein Bleach | B21: Half Back | C21: Gold | D21: 250 | E21: 10 | F21: =IF(E21="","",D21-E21) -> 240 | G21: =IFERROR(IF(E21="","",F21/D21),"") -> 0.96
A22: Protein Bleach | B22: Half Back | C22: Oxy | D22: 300 | E22: 10 | F22: =IF(E22="","",D22-E22) -> 290 | G22: =IFERROR(IF(E22="","",F22/D22),"") -> 0.96666667
A23: Protein Bleach | B23: Full Front | C23: Fruit | D23: 350 | E23: 10 | F23: =IF(E23="","",D23-E23) -> 340 | G23: =IFERROR(IF(E23="","",F23/D23),"") -> 0.97142857
A24: Protein Bleach | B24: Full Front | C24: Gold | D24: 400 | E24: 10 | F24: =IF(E24="","",D24-E24) -> 390 | G24: =IFERROR(IF(E24="","",F24/D24),"") -> 0.975
A25: Protein Bleach | B25: Full Front | C25: Oxy | D25: 450 | E25: 10 | F25: =IF(E25="","",D25-E25) -> 440 | G25: =IFERROR(IF(E25="","",F25/D25),"") -> 0.97777778
A26: Protein Bleach | B26: Full Back | C26: Fruit | D26: 350 | E26: 10 | F26: =IF(E26="","",D26-E26) -> 340 | G26: =IFERROR(IF(E26="","",F26/D26),"") -> 0.97142857
A27: Protein Bleach | B27: Full Back | C27: Gold | D27: 400 | E27: 10 | F27: =IF(E27="","",D27-E27) -> 390 | G27: =IFERROR(IF(E27="","",F27/D27),"") -> 0.975
A28: Protein Bleach | B28: Full Back | C28: Oxy | D28: 450 | E28: 10 | F28: =IF(E28="","",D28-E28) -> 440 | G28: =IFERROR(IF(E28="","",F28/D28),"") -> 0.97777778
... A30: Protein Bleach | B30: Arms | C30: Gold | D30: 400 | E30: 10 | F30: =IF(E30="","",D30-E30) -> 390 | G30: =IFERROR(IF(E30="","",F30/D30),"") -> 0.975
A31: Protein Bleach | B31: Arms | C31: Oxy | E31: 10 | F31: =IF(E31="","",D31-E31) -> -10 | G31: =IFERROR(IF(E31="","",F31/D31),"") | H31: Not listed on menu (variant not offered)
A32: Protein Bleach | B32: Legs | C32: Fruit | D32: 400 | E32: 10 | F32: =IF(E32="","",D32-E32) -> 390 | G32: =IFERROR(IF(E32="","",F32/D32),"") -> 0.975
A33: Protein Bleach | B33: Legs | C33: Gold | D33: 450 | E33: 10 | F33: =IF(E33="","",D33-E33) -> 440 | G33: =IFERROR(IF(E33="","",F33/D33),"") -> 0.97777778
A34: Protein Bleach | B34: Legs | C34: Oxy | E34: 10 | F34: =IF(E34="","",D34-E34) -> -10 | G34: =IFERROR(IF(E34="","",F34/D34),"") | H34: Not listed on menu (variant not offered)
A35: Protein Bleach | B35: Full Body | C35: Fruit | D35: 1000 | E35: 30 | F35: =IF(E35="","",D35-E35) -> 970 | G35: =IFERROR(IF(E35="","",F35/D35),"") -> 0.97
A36: Protein Bleach | B36: Full Body | C36: Gold | D36: 1200 | E36: 30 | F36: =IF(E36="","",D36-E36) -> 1170 | G36: =IFERROR(IF(E36="","",F36/D36),"") -> 0.975
A37: Protein Bleach | B37: Full Body | C37: Oxy | D37: 1500 | E37: 30 | F37: =IF(E37="","",D37-E37) -> 1470 | G37: =IFERROR(IF(E37="","",F37/D37),"") -> 0.98
A38: Face Bleach | B38: Prime | D38: 500 | E38: 30 | F38: =IF(E38="","",D38-E38) -> 470 | G38: =IFERROR(IF(E38="","",F38/D38),"") -> 0.94
A39: Face Bleach | B39: O3+ | D39: 550 | E39: 30 | F39: =IF(E39="","",D39-E39) -> 520 | G39: =IFERROR(IF(E39="","",F39/D39),"") -> 0.94545455
A40: Waxing | B40: Under Arms | C40: Normal | D40: 100 | E40: 20 | F40: =IF(E40="","",D40-E40) -> 80 | G40: =IFERROR(IF(E40="","",F40/D40),"") -> 0.8
A41: Waxing | B41: Under Arms | C41: White Chocolate | D41: 100 | E41: 20 | F41: =IF(E41="","",D41-E41) -> 80 | G41: =IFERROR(IF(E41="","",F41/D41),"") -> 0.8
...

Sheet Earnings
A1: S.No | B1: Date | C1: Items | D1: Money Received | E1: Payment Mode
A2: 1 | B2: 46251 | D2: 450 | E2: Online
A3: 2 | B3: 46252 | D3: 660 | E3: UPI
A4: 3 | B4: 46253 | D4: 1110 | E4: UPI
A5: 4 | B5: 46254 | D5: 250 | E5: UPI
A6: 5 | B6: 46255 | D6: 750 | E6: UPI
A7: 6 | B7: 46256
A8: 7 | B8: 46257
A9: 8 | B9: 46258 | D9: 1000 | E9: UPI
A10: 9 | B10: 46258 | D10: 1200 | E10: Cash
A11: 10 | B11: 46259
A12: 11 | B12: 46260 | D12: 630 | E12: UPI
A13: 12 | B13: 46261
A14: 13 | B14: 46262
A15: 14 | B15: 46263
A16: 15 | B16: 46264
A17: 16 | B17: 46265
A18: 17 | B18: 46266
A19: 18 | B19: 46267
A20: 19 | B20: 46268 | D20: 180 | E20: UPI
A21: 20 | B21: 46268 | D21: 450 | E21: Cash
A22: 21 | B22: 46270 | D22: 1240 | E22: UPI
A23: 22 | B23: 46270 | D23: 110 | E23: Cash
A24: 23 | B24: 46271 | D24: =300+80+150 -> 530 | E24: UPI
A25: 24 | B25: 46271 | D25: 150 | E25: Cash
A26: 25 | B26: 46272 | D26: =100+150+200 -> 450 | E26: UPI
A27: 26 | B27: 46272 | D27: 110 | E27: Cash
A28: 27 | B28: 46273 | D28: =450+150+150+80 -> 830 | E28: UPI
A29: 28 | B29: 46274 | D29: =400+100+100+200 -> 800 | E29: UPI
A30: 29 | B30: 46274 | D30: 1000 | E30: Cash
A31: 30 | B31: 46275 | D31: =150+100+900+150 -> 1300 | E31: UPI
A32: 31 | B32: 46276 | D32: =100+350+700+250+150+140 -> 1690 | E32: UPI
A33: 31 | B33: 46276 | D33: 50 | E33: Cash

Sheet Category Summary
A1: Category | B1: # of Services | C1: Avg Selling Price (Rs.) | D1: # with Cost Entered | E1: Avg Cost (Rs.) | F1: Avg Profit (Rs.) | G1: Avg Margin % | H1: Total Profit if Sold Once Each (Rs.)
A2: Threading | B2: =COUNTIF('Price List & Margins'!$A$2:$A$163,A2) -> 6 | C2: =IFERROR(AVERAGEIFS('Price List & Margins'!$D$2:$D$163,'Price List & Margins'!$A$2:$A$163,A2),"") -> 73.333333 | D2: =COUNTIFS('Price List & Margins'!$A$2:$A$163,A2,'Price List & Margins'!$E$2:$E$163,"<>") -> 6 | E2: =IFERROR(AVERAGEIFS('Price List & Margins'!$E$2:$E$163,'Price List & Margins'!$A$2:$A$163,A2),"") -> 6.6666667 | F2: =IFERROR(AVERAGEIFS('Price List & Margins'!$F$2:$F$163,'Price List & Margins'!$A$2:$A$163,A2),"") -> 66.666667 | G2: =IFERROR(AVERAGEIFS('Price List & Margins'!$G$2:$G$163,'Price List & Margins'!$A$2:$A$163,A2),"") -> 0.87333333 | H2: =IFERROR(SUMIFS('Price List & Margins'!$F$2:$F$163,'Price List & Margins'!$A$2:$A$163,A2),"") -> 400
A3: Brazilian Face Wax | B3: =COUNTIF('Price List & Margins'!$A$2:$A$163,A3) -> 6 | C3: =IFERROR(AVERAGEIFS('Price List & Margins'!$D$2:$D$163,'Price List & Margins'!$A$2:$A$163,A3),"") -> 116.66667 | D3: =COUNTIFS('Price List & Margins'!$A$2:$A$163,A3,'Price List & Margins'!$E$2:$E$163,"<>") -> 6 | E3: =IFERROR(AVERAGEIFS('Price List & Margins'!$E$2:$E$163,'Price List & Margins'!$A$2:$A$163,A3),"") -> 12.5 | F3: =IFERROR(AVERAGEIFS('Price List & Margins'!$F$2:$F$163,'Price List & Margins'!$A$2:$A$163,A3),"") -> 104.16667 | G3: =IFERROR(AVERAGEIFS('Price List & Margins'!$G$2:$G$163,'Price List & Margins'!$A$2:$A$163,A3),"") -> 0.90416667 | H3: =IFERROR(SUMIFS('Price List & Margins'!$F$2:$F$163,'Price List & Margins'!$A$2:$A$163,A3),"") -> 625
A4: Protein Bleach | B4: =COUNTIF('Price List & Margins'!$A$2:$A$163,A4) -> 24 | C4: =IFERROR(AVERAGEIFS('Price List & Margins'!$D$2:$D$163,'Price List & Margins'!$A$2:$A$163,A4),"") -> 454.54545 | D4: =COUNTIFS('Price List & Margins'!$A$2:$A$163,A4,'Price List & Margins'!$E$2:$E$163,"<>") -> 24 | E4: =IFERROR(AVERAGEIFS('Price List & Margins'!$E$2:$E$163,'Price List & Margins'!$A$2:$A$163,A4),"") -> 12.5 | F4: =IFERROR(AVERAGEIFS('Price List & Margins'!$F$2:$F$163,'Price List & Margins'!$A$2:$A$163,A4),"") -> 404.16667 | G4: =IFERROR(AVERAGEIFS('Price List & Margins'!$G$2:$G$163,'Price List & Margins'!$A$2:$A$163,A4),"") -> 0.96875541 | H4: =IFERROR(SUMIFS('Price List & Margins'!$F$2:$F$163,'Price List & Margins'!$A$2:$A$163,A4),"") -> 9700
A5: Face Bleach | B5: =COUNTIF('Price List & Margins'!$A$2:$A$163,A5) -> 2 | C5: =IFERROR(AVERAGEIFS('Price List & Margins'!$D$2:$D$163,'Price List & Margins'!$A$2:$A$163,A5),"") -> 525 | D5: =COUNTIFS('Price List & Margins'!$A$2:$A$163,A5,'Price List & Margins'!$E$2:$E$163,"<>") -> 2 | E5: =IFERROR(AVERAGEIFS('Price List & Margins'!$E$2:$E$163,'Price List & Margins'!$A$2:$A$163,A5),"") -> 30 | F5: =IFERROR(AVERAGEIFS('Price List & Margins'!$F$2:$F$163,'Price List & Margins'!$A$2:$A$163,A5),"") -> 495 | G5: =IFERROR(AVERAGEIFS('Price List & Margins'!$G$2:$G$163,'Price List & Margins'!$A$2:$A$163,A5),"") -> 0.94272727 | H5: =IFERROR(SUMIFS('Price List & Margins'!$F$2:$F$163,'Price List & Margins'!$A$2:$A$163,A5),"") -> 990
A6: Waxing | B6: =COUNTIF('Price List & Margins'!$A$2:$A$163,A6) -> 25 | C6: =IFERROR(AVERAGEIFS('Price List & Margins'!$D$2:$D$163,'Price List & Margins'!$A$2:$A$163,A6),"") -> 552 | D6: =COUNTIFS('Price List & Margins'!$A$2:$A$163,A6,'Price List & Margins'!$E$2:$E$163,"<>") -> 25 | E6: =IFERROR(AVERAGEIFS('Price List & Margins'!$E$2:$E$163,'Price List & Margins'!$A$2:$A$163,A6),"") -> 43.2 | F6: =IFERROR(AVERAGEIFS('Price List & Margins'!$F$2:$F$163,'Price List & Margins'!$A$2:$A$163,A6),"") -> 508.8 | G6: =IFERROR(AVERAGEIFS('Price List & Margins'!$G$2:$G$163,'Price List & Margins'!$A$2:$A$163,A6),"") -> 0.89424488 | H6: =IFERROR(SUMIFS('Price List & Margins'!$F$2:$F$163,'Price List & Margins'!$A$2:$A$163,A6),"") -> 12720
A7: Cleanups | B7: =COUNTIF('Price List & Margins'!$A$2:$A$163,A7) -> 4 | C7: =IFERROR(AVERAGEIFS('Price List & Margins'!$D$2:$D$163,'Price List & Margins'!$A$2:$A$163,A7),"") -> 500 | D7: =COUNTIFS('Price List & Margins'!$A$2:$A$163,A7,'Price List & Margins'!$E$2:$E$163,"<>") -> 4 | E7: =IFERROR(AVERAGEIFS('Price List & Margins'!$E$2:$E$163,'Price List & Margins'!$A$2:$A$163,A7),"") -> 70 | F7: =IFERROR(AVERAGEIFS('Price List & Margins'!$F$2:$F$163,'Price List & Margins'!$A$2:$A$163,A7),"") -> 430 | G7: =IFERROR(AVERAGEIFS('Price List & Margins'!$G$2:$G$163,'Price List & Margins'!$A$2:$A$163,A7),"") -> 0.87958333 | H7: =IFERROR(SUMIFS('Price List & Margins'!$F$2:$F$163,'Price List & Margins'!$A$2:$A$163,A7),"") -> 1720
A8: Exotic Facials | B8: =COUNTIF('Price List & Margins'!$A$2:$A$163,A8) -> 12 | C8: =IFERROR(AVERAGEIFS('Price List & Margins'!$D$2:$D$163,'Price List & Margins'!$A$2:$A$163,A8),"") -> 1058.3333 | D8: =COUNTIFS('Price List & Margins'!$A$2:$A$163,A8,'Price List & Margins'!$E$2:$E$163,"<>") -> 12 | E8: =IFERROR(AVERAGEIFS('Price List & Margins'!$E$2:$E$163,'Price List & Margins'!$A$2:$A$163,A8),"") -> 250 | F8: =IFERROR(AVERAGEIFS('Price List & Margins'!$F$2:$F$163,'Price List & Margins'!$A$2:$A$163,A8),"") -> 808.33333 | G8: =IFERROR(AVERAGEIFS('Price List & Margins'!$G$2:$G$163,'Price List & Margins'!$A$2:$A$163,A8),"") -> 0.74305556 | H8: =IFERROR(SUMIFS('Price List & Margins'!$F$2:$F$163,'Price List & Margins'!$A$2:$A$163,A8),"") -> 9700
A9: Luxury Facials | B9: =COUNTIF('Price List & Margins'!$A$2:$A$163,A9) -> 10 | C9: =IFERROR(AVERAGEIFS('Price List & Margins'!$D$2:$D$163,'Price List & Margins'!$A$2:$A$163,A9),"") -> 2722.2222 | D9: =COUNTIFS('Price List & Margins'!$A$2:$A$163,A9,'Price List & Margins'!$E$2:$E$163,"<>") -> 9 | E9: =IFERROR(AVERAGEIFS('Price List & Margins'!$E$2:$E$163,'Price List & Margins'!$A$2:$A$163,A9),"") -> 224.44444 | F9: =IFERROR(AVERAGEIFS('Price List & Margins'!$F$2:$F$163,'Price List & Margins'!$A$2:$A$163,A9),"") -> 2497.7778 | G9: =IFERROR(AVERAGEIFS('Price List & Margins'!$G$2:$G$163,'Price List & Margins'!$A$2:$A$163,A9),"") -> 0.91001323 | H9: =IFERROR(SUMIFS('Price List & Margins'!$F$2:$F$163,'Price List & Margins'!$A$2:$A$163,A9),"") -> 22480
A10: D-Tan | B10: =COUNTIF('Price List & Margins'!$A$2:$A$163,A10) -> 4 | C10: =IFERROR(AVERAGEIFS('Price List & Margins'!$D$2:$D$163,'Price List & Margins'!$A$2:$A$163,A10),"") -> 400 | D10: =COUNTIFS('Price List & Margins'!$A$2:$A$163,A10,'Price List & Margins'!$E$2:$E$163,"<>") -> 4 | E10: =IFERROR(AVERAGEIFS('Price List & Margins'!$E$2:$E$163,'Price List & Margins'!$A$2:$A$163,A10),"") -> 192.5 | F10: =IFERROR(AVERAGEIFS('Price List & Margins'!$F$2:$F$163,'Price List & Margins'!$A$2:$A$163,A10),"") -> 107.5 | G10: =IFERROR(AVERAGEIFS('Price List & Margins'!$G$2:$G$163,'Price List & Margins'!$A$2:$A$163,A10),"") -> 0.60277778 | H10: =IFERROR(SUMIFS('Price List & Margins'!$F$2:$F$163,'Price List & Margins'!$A$2:$A$163,A10),"") -> 430
A11: Manicure | B11: =COUNTIF('Price List & Margins'!$A$2:$A$163,A11) -> 4 | C11: =IFERROR(AVERAGEIFS('Price List & Margins'!$D$2:$D$163,'Price List & Margins'!$A$2:$A$163,A11),"") -> 512.5 | D11: =COUNTIFS('Price List & Margins'!$A$2:$A$163,A11,'Price List & Margins'!$E$2:$E$163,"<>") -> 4 | E11: =IFERROR(AVERAGEIFS('Price List & Margins'!$E$2:$E$163,'Price List & Margins'!$A$2:$A$163,A11),"") -> 20 | F11: =IFERROR(AVERAGEIFS('Price List & Margins'!$F$2:$F$163,'Price List & Margins'!$A$2:$A$163,A11),"") -> 492.5 | G11: =IFERROR(AVERAGEIFS('Price List & Margins'!$G$2:$G$163,'Price List & Margins'!$A$2:$A$163,A11),"") -> 0.96070707 | H11: =IFERROR(SUMIFS('Price List & Margins'!$F$2:$F$163,'Price List & Margins'!$A$2:$A$163,A11),"") -> 1970
A12: Pedicure | B12: =COUNTIF('Price List & Margins'!$A$2:$A$163,A12) -> 4 | C12: =IFERROR(AVERAGEIFS('Price List & Margins'!$D$2:$D$163,'Price List & Margins'!$A$2:$A$163,A12),"") -> 600 | D12: =COUNTIFS('Price List & Margins'!$A$2:$A$163,A12,'Price List & Margins'!$E$2:$E$163,"<>") -> 4 | E12: =IFERROR(AVERAGEIFS('Price List & Margins'!$E$2:$E$163,'Price List & Margins'!$A$2:$A$163,A12),"") -> 20 | F12: =IFERROR(AVERAGEIFS('Price List & Margins'!$F$2:$F$163,'Price List & Margins'!$A$2:$A$163,A12),"") -> 580 | G12: =IFERROR(AVERAGEIFS('Price List & Margins'!$G$2:$G$163,'Price List & Margins'!$A$2:$A$163,A12),"") -> 0.96543901 | H12: =IFERROR(SUMIFS('Price List & Margins'!$F$2:$F$163,'Price List & Margins'!$A$2:$A$163,A12),"") -> 2320
A13: Hair Cut | B13: =COUNTIF('Price List & Margins'!$A$2:$A$163,A13) -> 6 | C13: =IFERROR(AVERAGEIFS('Price List & Margins'!$D$2:$D$163,'Price List & Margins'!$A$2:$A$163,A13),"") -> 241.66667 | D13: =COUNTIFS('Price List & Margins'!$A$2:$A$163,A13,'Price List & Margins'!$E$2:$E$163,"<>") -> 6 | E13: =IFERROR(AVERAGEIFS('Price List & Margins'!$E$2:$E$163,'Price List & Margins'!$A$2:$A$163,A13),"") -> 10 | F13: =IFERROR(AVERAGEIFS('Price List & Margins'!$F$2:$F$163,'Price List & Margins'!$A$2:$A$163,A13),"") -> 231.66667 | G13: =IFERROR(AVERAGEIFS('Price List & Margins'!$G$2:$G$163,'Price List & Margins'!$A$2:$A$163,A13),"") -> 0.95833333 | H13: =IFERROR(SUMIFS('Price List & Margins'!$F$2:$F$163,'Price List & Margins'!$A$2:$A$163,A13),"") -> 1390
... A23: Packages | B23: =COUNTIF('Price List & Margins'!$A$2:$A$163,A23) -> 6 | C23: =IFERROR(AVERAGEIFS('Price List & Margins'!$D$2:$D$163,'Price List & Margins'!$A$2:$A$163,A23),"") -> 1833.3333 | D23: =COUNTIFS('Price List & Margins'!$A$2:$A$163,A23,'Price List & Margins'!$E$2:$E$163,"<>") -> 6 | E23: =IFERROR(AVERAGEIFS('Price List & Margins'!$E$2:$E$163,'Price List & Margins'!$A$2:$A$163,A23),"") -> 80 | F23: =IFERROR(AVERAGEIFS('Price List & Margins'!$F$2:$F$163,'Price List & Margins'!$A$2:$A$163,A23),"") -> 1753.3333 | G23: =IFERROR(AVERAGEIFS('Price List & Margins'!$G$2:$G$163,'Price List & Margins'!$A$2:$A$163,A23),"") -> 0.95411861 | H23: =IFERROR(SUMIFS('Price List & Margins'!$F$2:$F$163,'Price List & Margins'!$A$2:$A$163,A23),"") -> 10520
A24: SALON-WIDE TOTAL / AVERAGE | B24: =SUM(B2:B23) -> 162 | C24: =IFERROR(AVERAGE('Price List & Margins'!$D$2:$D$163),"") -> 1166.0759 | D24: =SUM(D2:D23) -> 151 | E24: =IFERROR(AVERAGEIF('Price List & Margins'!$E$2:$E$163,"<>"),"") -> 80.529801 | F24: =IFERROR(AVERAGEIF('Price List & Margins'!$E$2:$E$163,"<>",'Price List & Margins'!$F$2:$F$163),"") -> 807.81457 | G24: =IFERROR(AVERAGEIF('Price List & Margins'!$E$2:$E$163,"<>",'Price List & Margins'!$G$2:$G$163),"") -> 0.90648634 | H24: =SUM(H2:H23) -> 121980
A26: Averages/totals for Cost, Profit and Margin only include rows where you have entered a Cost per Service on the 'Price List & Margins' tab. Fill in more costs there to make this summary more complete.

Sheet Inventory
A1: Skin aloe vera wax | B1: 2
A2: Skin white chocolate wax | B2: 3
A3: Waxing stick | B3: 2 packet
A4: O3 facial | B4: 2
A5: Lotus facial kit | B5: 2
A6: Threading thread | B6: 1 set
A7: Mixed fruit massage cream - | B7: 1 box
A8: Foot care salt rose | B8: 1
A9: Gel.massage cream | B9: 1
A10: Nail polish - light colour | B10: 1 box
A11: Facial tissue- | B11: 2 packet 100 piece
A12: Blossom kochar aroma magic | B12: 2
A13: Rica wax | B13: 1
A14: White chocolate | B14: 2
A15: Vlcc instant glow facial kit | B15: 1 big packet
A16: Vlcc gold bleach | B16: 1 box
A17: Massage coconut oil | B17: 1
A18: Manicure pedicure tools kit | B18: 1
A19: Fold paper | B19: 1
A20: Gillette blade | B20: 1 box
A21: Smoothening cream (streax) | B21: 1 big box
A22: Keratine(protac) | B22: 1
A23: Bella hair care | B23: 60 capsule
A24: Round brush | B24: 1
A25: Lotus gel | B25: 1
A26: O3 - detan | B26: 1
A27: Comb machine trimmer | B27: -1,2,3
A28: Loreal colour - | B28: 4, 3 , 4.26,4.65
A29: Loreal hair spa | B29: 4, 3 , 4.26,4.65
